Workbook

Sheet Oversigt
A1: Snublesten i Danmark – arbejdsregister
A2: Status pr. 24. okt. 2026. Tallene nedenfor tæller fra fanen Register og opdaterer sig, når du tilføjer rækker.
A4: Sten i alt | B4: =COUNTA(Register!$A$2:$A$2000) -> 210
A5: Med koordinat | B5: =COUNT(Register!$I$2:$I$2000) -> 187
A6: Med dansk original-indskrift | B6: =COUNTIF(Register!$O$2:$O$2000,"?*") -> 6
A7: Med Wikidata-item | B7: =COUNTIF(Register!$S$2:$S$2000,"Q*") -> 10
A8: Med OSM-node | B8: =COUNTIF(Register!$T$2:$T$2000,"?*") -> 37
A9: Skal verificeres / afvigelse | B9: =COUNTIF(Register!$V$2:$V$2000,"Skal verificeres")+COUNTIF(Register!$V$2:$V$2000,"Afvigelse – tjek") -> 11
A11: Kommune | B11: Sten | C11: Ældste nedlæggelse | D11: Nyeste nedlæggelse | F11: Sat af | G11: Sten
A12: København | B12: =COUNTIF(Register!$H$2:$H$2000,A12) -> 107 | C12: =_xlfn.MINIFS(Register!$L$2:$L$2000,Register!$H$2:$H$2000,A12) -> 2019 | D12: =_xlfn.MAXIFS(Register!$L$2:$L$2000,Register!$H$2:$H$2000,A12) -> 2026 | F12: Snublesten Danmark | G12: =COUNTIF(Register!$N$2:$N$2000,F12) -> 182
A13: Frederiksberg | B13: =COUNTIF(Register!$H$2:$H$2000,A13) -> 28 | C13: =_xlfn.MINIFS(Register!$L$2:$L$2000,Register!$H$2:$H$2000,A13) -> 2019 | D13: =_xlfn.MAXIFS(Register!$L$2:$L$2000,Register!$H$2:$H$2000,A13) -> 2026 | F13: Snublesten Fyn | G13: =COUNTIF(Register!$N$2:$N$2000,F13) -> 23
A14: Gentofte | B14: =COUNTIF(Register!$H$2:$H$2000,A14) -> 22 | C14: =_xlfn.MINIFS(Register!$L$2:$L$2000,Register!$H$2:$H$2000,A14) -> 2020 | D14: =_xlfn.MAXIFS(Register!$L$2:$L$2000,Register!$H$2:$H$2000,A14) -> 2026 | F14: Historisk Forening Skærbæk (?) | G14: =COUNTIF(Register!$N$2:$N$2000,F14) -> 3
A15: Odense | B15: =COUNTIF(Register!$H$2:$H$2000,A15) -> 15 | C15: =_xlfn.MINIFS(Register!$L$2:$L$2000,Register!$H$2:$H$2000,A15) -> 2021 | D15: =_xlfn.MAXIFS(Register!$L$2:$L$2000,Register!$H$2:$H$2000,A15) -> 2026 | F15: Ukendt | G15: =COUNTIF(Register!$N$2:$N$2000,F15) -> 1
A16: Nyborg | B16: =COUNTIF(Register!$H$2:$H$2000,A16) -> 5 | C16: =_xlfn.MINIFS(Register!$L$2:$L$2000,Register!$H$2:$H$2000,A16) -> 2024 | D16: =_xlfn.MAXIFS(Register!$L$2:$L$2000,Register!$H$2:$H$2000,A16) -> 2026 | F16: Snublesten Fyn / Snublesten Danmark | G16: =COUNTIF(Register!$N$2:$N$2000,F16) -> 1
A17: Kolding | B17: =COUNTIF(Register!$H$2:$H$2000,A17) -> 5 | C17: =_xlfn.MINIFS(Register!$L$2:$L$2000,Register!$H$2:$H$2000,A17) -> 2021 | D17: =_xlfn.MAXIFS(Register!$L$2:$L$2000,Register!$H$2:$H$2000,A17) -> 2021
A18: Randers | B18: =COUNTIF(Register!$H$2:$H$2000,A18) -> 5 | C18: =_xlfn.MINIFS(Register!$L$2:$L$2000,Register!$H$2:$H$2000,A18) -> 2023 | D18: =_xlfn.MAXIFS(Register!$L$2:$L$2000,Register!$H$2:$H$2000,A18) -> 2023
A19: Aarhus | B19: =COUNTIF(Register!$H$2:$H$2000,A19) -> 4 | C19: =_xlfn.MINIFS(Register!$L$2:$L$2000,Register!$H$2:$H$2000,A19) -> 2022 | D19: =_xlfn.MAXIFS(Register!$L$2:$L$2000,Register!$H$2:$H$2000,A19) -> 2022
A20: Lyngby-Taarbæk | B20: =COUNTIF(Register!$H$2:$H$2000,A20) -> 3 | C20: =_xlfn.MINIFS(Register!$L$2:$L$2000,Register!$H$2:$H$2000,A20) -> 2021 | D20: =_xlfn.MAXIFS(Register!$L$2:$L$2000,Register!$H$2:$H$2000,A20) -> 2026
A21: Vejle | B21: =COUNTIF(Register!$H$2:$H$2000,A21) -> 3 | C21: =_xlfn.MINIFS(Register!$L$2:$L$2000,Register!$H$2:$H$2000,A21) -> 2023 | D21: =_xlfn.MAXIFS(Register!$L$2:$L$2000,Register!$H$2:$H$2000,A21) -> 2023
A22: Tønder | B22: =COUNTIF(Register!$H$2:$H$2000,A22) -> 3 | C22: =_xlfn.MINIFS(Register!$L$2:$L$2000,Register!$H$2:$H$2000,A22) -> 2025 | D22: =_xlfn.MAXIFS(Register!$L$2:$L$2000,Register!$H$2:$H$2000,A22) -> 2025
A23: Svendborg | B23: =COUNTIF(Register!$H$2:$H$2000,A23) -> 3 | C23: =_xlfn.MINIFS(Register!$L$2:$L$2000,Register!$H$2:$H$2000,A23) -> 2022 | D23: =_xlfn.MAXIFS(Register!$L$2:$L$2000,Register!$H$2:$H$2000,A23) -> 2022
A24: Dragør | B24: =COUNTIF(Register!$H$2:$H$2000,A24) -> 2 | C24: =_xlfn.MINIFS(Register!$L$2:$L$2000,Register!$H$2:$H$2000,A24) -> 2024 | D24: =_xlfn.MAXIFS(Register!$L$2:$L$2000,Register!$H$2:$H$2000,A24) -> 2026
A25: Assens | B25: =COUNTIF(Register!$H$2:$H$2000,A25) -> 2 | C25: =_xlfn.MINIFS(Register!$L$2:$L$2000,Register!$H$2:$H$2000,A25) -> 2022 | D25: =_xlfn.MAXIFS(Register!$L$2:$L$2000,Register!$H$2:$H$2000,A25) -> 2022
A26: Vordingborg | B26: =COUNTIF(Register!$H$2:$H$2000,A26) -> 1 | C26: =_xlfn.MINIFS(Register!$L$2:$L$2000,Register!$H$2:$H$2000,A26) -> 2023 | D26: =_xlfn.MAXIFS(Register!$L$2:$L$2000,Register!$H$2:$H$2000,A26) -> 2023
A27: Gladsaxe | B27: =COUNTIF(Register!$H$2:$H$2000,A27) -> 1 | C27: =_xlfn.MINIFS(Register!$L$2:$L$2000,Register!$H$2:$H$2000,A27) -> 2024 | D27: =_xlfn.MAXIFS(Register!$L$2:$L$2000,Register!$H$2:$H$2000,A27) -> 2024
A28: Holbæk | B28: =COUNTIF(Register!$H$2:$H$2000,A28) -> 1 | C28: =_xlfn.MINIFS(Register!$L$2:$L$2000,Register!$H$2:$H$2000,A28) -> 2025 | D28: =_xlfn.MAXIFS(Register!$L$2:$L$2000,Register!$H$2:$H$2000,A28) -> 2025
A29: I alt | B29: =SUM(B12:B28) -> 210

Sheet Register
A1: ID | B1: Navn | C1: Født (år) | D1: Udfald | E1: Adresse | F1: Postnr | G1: By | H1: Kommune | I1: Bredde | J1: Længde | K1: Koordinat-kilde | L1: Nedlagt (år) | M1: Nedlagt (dato) | N1: Sat af | O1: Indskrift (dansk, original) | P1: Indskrift (tysk oversættelse, de.wikipedia) | Q1: Primær kilde | R1: snublesten.dk-ID | S1: Wikidata | T1: OSM-node | U1: Commons-foto | V1: Status | W1: Note
A2: DK-0001 | B2: Emma Augusta Hansen | E2: Vestergade 84 | F2: 8000 | G2: Aarhus C | H2: Aarhus | I2: 56.157107 | J2: 10.197486 | K2: snublesten.dk | L2: 2022 | N2: Snublesten Danmark | Q2: https://snublesten.dk/snublesten/emma-augusta-hansen/ | R2: 913 | T2: 10946691693 | V2: Fra gruppens egen liste | W2: Én OSM-node uden navn dækker familiens 4 sten
A3: DK-0002 | B3: Ib Hansen | E3: Vestergade 84 | F3: 8000 | G3: Aarhus C | H3: Aarhus | I3: 56.157187 | J3: 10.197476 | K3: snublesten.dk | L3: 2022 | N3: Snublesten Danmark | Q3: https://snublesten.dk/snublesten/ib-hansen/ | R3: 915 | T3: 10946691693 | V3: Fra gruppens egen liste | W3: Én OSM-node uden navn dækker familiens 4 sten
A4: DK-0003 | B4: Preben Hansen | E4: Vestergade 84 | F4: 8000 | G4: Aarhus C | H4: Aarhus | I4: 56.157067 | J4: 10.197546 | K4: snublesten.dk | L4: 2022 | N4: Snublesten Danmark | Q4: https://snublesten.dk/snublesten/preben-hansen/ | R4: 916 | T4: 10946691693 | V4: Fra gruppens egen liste | W4: Én OSM-node uden navn dækker familiens 4 sten
A5: DK-0004 | B5: Thorvald Hansen | E5: Vestergade 84 | F5: 8000 | G5: Aarhus C | H5: Aarhus | I5: 56.156997 | J5: 10.197646 | K5: snublesten.dk | L5: 2022 | N5: Snublesten Danmark | Q5: https://snublesten.dk/snublesten/thorvald-hansen/ | R5: 909 | T5: 10946691693 | V5: Fra gruppens egen liste | W5: Én OSM-node uden navn dækker familiens 4 sten
A6: DK-0005 | B6: Julius Joseph Moritz | C6: 1882 | D6: Omkom | E6: Dommergården (adresse mangler) | F6: 5610 | G6: Assens | H6: Assens | L6: 2022 | M6: 2022-06-08 | N6: Snublesten Fyn | Q6: https://www.snublestenfyn.dk/snublesten-i-assens | V6: Fra gruppens egen side | W6: Dommer; døde i Theresienstadt 8.4.1945
A7: DK-0006 | B7: Viggo Johannes Hansen | C7: 1896 | D7: Omkom | E7: Østergade 38 | F7: 5610 | G7: Assens | H7: Assens | L7: 2022 | M7: 2022-06-08 | N7: Snublesten Fyn | Q7: https://www.snublestenfyn.dk/snublesten-i-assens | V7: Fra gruppens egen side | W7: Clearingmyrdet 19.4.1945
A8: DK-0007 | B8: Jørgen Emil Thers | E8: Hovedgaden 34 | F8: 2791 | G8: Dragør | H8: Dragør | I8: 55.596799 | J8: 12.635227 | K8: snublesten.dk | L8: 2026 | N8: Snublesten Danmark | Q8: https://snublesten.dk/snublesten/joergen-emil-thers/ | R8: 3245 | V8: Fra gruppens egen liste
A9: DK-0008 | B9: Ellen Wilhelmine Nielsen | E9: Rønne Allé 42 | F9: 2770 | G9: Dragør | H9: Dragør | I9: 55.591282 | J9: 12.673444 | K9: snublesten.dk | L9: 2024 | N9: Snublesten Danmark | Q9: https://snublesten.dk/snublesten/ellen-wilhelmine-nielsen/ | R9: 2373 | V9: Afvigelse – tjek | W9: Postnr 2770 er Kastrup, men by angivet som Dragør (2791)
A10: DK-0009 | B10: Gabrielle Salmonsen | C10: 1855 | D10: Omkom | E10: Bianco Lunos Allé 1 | F10: 1868 | G10: Frederiksberg C | H10: Frederiksberg | I10: 55.676893 | J10: 12.540168 | K10: snublesten.dk | L10: 2020 | N10: Snublesten Danmark | P10: HIER WOHNTE / GABRIELLE / SALMONSEN / GEB. HEIMANN 1855 / VERHAFTET 2.10.1943 / DEPORTIERT 1943 / THERESIENSTADT / UMGEKOMMEN 10.2.1944 | Q10: https://snublesten.dk/snublesten/gabrielle-salmonsen/ | R10: 539 | U10: Stolperstein für Gabrielle Salmonsen (Frederiksberg).jpg | V10: Fra gruppens egen liste
A11: DK-0010 | B11: Jacob Thalmay | C11: 1904 | D11: Omkom | E11: Carl Plougsvej 7 | F11: 1913 | G11: Frederiksberg C | H11: Frederiksberg | I11: 55.679161 | J11: 12.552644 | K11: snublesten.dk | L11: 2019 | N11: Snublesten Danmark | P11: HIER WOHNTE / JACOB THALMAY / GEBOREN 1904 / DEPORTIERT 1944 / SACHSENHAUSEN / AUSCHWITZ / UMGEKOMMEN 9.3.1945 / TODESMARSCH NACH MELK | Q11: https://snublesten.dk/snublesten/jacob-thalmay/ | R11: 182 | S11: Q64691522 | U11: Stolperstein für Jacob Thalmay (Frederiksberg).jpg | V11: Fra gruppens egen liste
A12: DK-0011 | B12: "Jeanne" Johanne Nathansen | E12: Drosselvej 6 | F12: 2000 | G12: Frederiksberg | H12: Frederiksberg | I12: 55.689206 | J12: 12.523745 | K12: snublesten.dk | L12: 2026 | N12: Snublesten Danmark | Q12: https://snublesten.dk/snublesten/jeanne-johanne-nathansen/ | R12: 3208 | V12: Fra gruppens egen liste
A13: DK-0012 | B13: Henri Nathansen | E13: Drosselvej 6 | F13: 2000 | G13: Frederiksberg | H13: Frederiksberg | I13: 55.689256 | J13: 12.523655 | K13: snublesten.dk | L13: 2026 | N13: Snublesten Danmark | Q13: https://snublesten.dk/snublesten/henri-nathansen/ | R13: 3207 | V13: Fra gruppens egen liste
A14: DK-0013 | B14: Elieser Cipikoff | E14: Falkoner Allé 38 | F14: 2000 | G14: Frederiksberg | H14: Frederiksberg | I14: 55.682217 | J14: 12.535448 | K14: snublesten.dk | L14: 2026 | N14: Snublesten Danmark | Q14: https://snublesten.dk/snublesten/elieser-cipikoff/ | R14: 3267 | V14: Fra gruppens egen liste
A15: DK-0014 | B15: Nechama Lea Cipikoff | E15: Falkoner Allé 38 | F15: 2000 | G15: Frederiksberg | H15: Frederiksberg | I15: 55.682147 | J15: 12.535438 | K15: snublesten.dk | L15: 2026 | N15: Snublesten Danmark | Q15: https://snublesten.dk/snublesten/nechama-lea-cipikoff/ | R15: 3271 | V15: Fra gruppens egen liste
A16: DK-0015 | B16: Noah Abraham Cipikoff | E16: Falkoner Allé 38 | F16: 2000 | G16: Frederiksberg | H16: Frederiksberg | I16: 55.682207 | J16: 12.535448 | K16: snublesten.dk | L16: 2026 | N16: Snublesten Danmark | Q16: https://snublesten.dk/snublesten/noah-abraham-cipikoff/ | R16: 3236 | V16: Fra gruppens egen liste
A17: DK-0016 | B17: Carl Joseph Glückstadt | C17: 1882 | D17: Omkom | E17: Forchhammersvej 5 | F17: 1920 | G17: Frederiksberg C | H17: Frederiksberg | I17: 55.679368 | J17: 12.554004 | K17: snublesten.dk | L17: 2020 | N17: Snublesten Danmark | P17: HIER WOHNTE / CARL JOSEPH / GLÜCKSTADT / GEBOREN 1882 / VERHAFTET 1943 / DEPORTIERT / THERESIENSTADT / UMGEKOMMEN 15.11.1943 | Q17: https://snublesten.dk/snublesten/carl-joseph-gluckstadt/ | R17: 537 | U17: Stolperstein für Carl Joseph Glückstadt (Frederiksberg).jpg | V17: Fra gruppens egen liste
A18: DK-0017 | B18: Olga Johanne Glückstadt | E18: Forchhammersvej 5 | F18: 1920 | G18: Frederiksberg C | H18: Frederiksberg | I18: 55.679268 | J18: 12.553914 | K18: snublesten.dk | L18: 2025 | N18: Snublesten Danmark | Q18: https://snublesten.dk/snublesten/olga-johanne-gluckstadt/ | R18: 2793 | V18: Fra gruppens egen liste
A19: DK-0018 | B19: Max Hartwig | C19: 1867 | D19: Overlevede | E19: Frydendalsvej 33 | F19: 1809 | G19: Frederiksberg C | H19: Frederiksberg | I19: 55.67082 | J19: 12.535348 | K19: snublesten.dk | L19: 2022 | N19: Snublesten Danmark | P19: HIER WOHNTE / MAX HARTWIG / 'GUBBEN' / GEBOREN 1867 / VERHAFTET 1.10.1943 / DEPORTIERT 1943 / THERESIENSTADT / BEFREIT | Q19: https://snublesten.dk/snublesten/max-hartwig/ | R19: 897 | U19: Stolperstein für Max Hartwig (Frederiksberg).jpg | V19: Fra gruppens egen liste
A20: DK-0019 | B20: Rose Hartwig | C20: 1880 | D20: Omkom | E20: Frydendalsvej 33 | F20: 1809 | G20: Frederiksberg C | H20: Frederiksberg | I20: 55.67087 | J20: 12.535488 | K20: snublesten.dk | L20: 2022 | N20: Snublesten Danmark | P20: HIER WOHNTE / ROSE HARTWIG / GEB. SALOMON 1880 / VERHAFTET 1.10.1943 / DEPORTIERT 1943 / THERESIENSTADT / ERMORDET 25.2.1944 | Q20: https://snublesten.dk/snublesten/rose-hartwig/ | R20: 896 | U20: Stolperstein für Rose Hartwig (Frederiksberg).jpg | V20: Fra gruppens egen liste
A21: DK-0020 | B21: Johanne Caroline Gray | E21: Godthåbsvej 131 | F21: 2000 | G21: Frederiksberg | H21: Frederiksberg | I21: 55.690045 | J21: 12.516996 | K21: snublesten.dk | L21: 2024 | N21: Snublesten Danmark | Q21: https://snublesten.dk/snublesten/johanne-caroline-gray/ | R21: 2310 | V21: Fra gruppens egen liste
A22: DK-0021 | B22: Ada Elvira Bomhoff | C22: 1892 | D22: Overlevede | E22: Harsdorffsvej 7 | F22: 1874 | G22: Frederiksberg C | H22: Frederiksberg | I22: 55.679716 | J22: 12.546309 | K22: snublesten.dk | L22: 2021 | N22: Snublesten Danmark | P22: HIER WOHNTE / ADA ELVIRA / BOMHOFF / GEB. ALS REICHMANN 1892 / UNTERSTÜTZTE DIE / WIDERSTANDSBEWEGUNG / VERHAFTET 4.9.1944 / INTERNIERUNGSLAGER FRØSLEV / BEFREIT | Q22: https://snublesten.dk/snublesten/ada-elvira-bomhoff/ | R22: 922 | U22: Stolperstein für Ada Elvira Bomhoff (Frederiksberg).jpg | V22: Fra gruppens egen liste
A23: DK-0022 | B23: Gunnar Johan Bomhoff | C23: 1887 | D23: Omkom | E23: Harsdorffsvej 7 | F23: 1874 | G23: Frederiksberg C | H23: Frederiksberg | I23: 55.679886 | J23: 12.546349 | K23: snublesten.dk | L23: 2021 | N23: Snublesten Danmark | P23: HIER WOHNTE / GUNNAR JOHAN / BOMHOFF / GEB. 1887 / VERHAFTET 18.10.1944 / DEPORTIERT 1945 / DACHAU / ERMORDET 13.4.1945 / NEUENGAMME | Q23: https://snublesten.dk/snublesten/gunnar-johan-bomhoff/ | R23: 921 | U23: Stolperstein für Gunnar Johan Bomhoff (Frederiksberg).jpg | V23: Fra gruppens egen liste
A24: DK-0023 | B24: Sam Besekow | C24: 1911 | D24: Overlevede | E24: Hollændervej 11 | F24: 1855 | G24: Frederiksberg C | H24: Frederiksberg | I24: 55.675991 | J24: 12.535976 | K24: snublesten.dk | L24: 2022 | N24: Snublesten Danmark | P24: HIER WOHNTE / SAMUEL 'SAM' / BESEKOW / GEBOREN 1911 / VERHAFTET 29.8.1943 / INTERNIERT IN HORSERØD / FREIGELASSEN 15.10.1943 / FLUCHT NACH SCHWEDEN / 22.10.1943 | Q24: https://snublesten.dk/snublesten/samuel-besekow/ | R24: 582 | U24: Stolperstein für Samuel Besekow (Frederiksberg).jpg | V24: Fra gruppens egen liste
A25: DK-0024 | B25: Frants Aleks Karl Sundstrøm | E25: Howitzvej 30 | F25: 2000 | G25: Frederiksberg | H25: Frederiksberg | I25: 55.679931 | J25: 12.529438 | K25: snublesten.dk | L25: 2024 | N25: Snublesten Danmark | Q25: https://snublesten.dk/snublesten/frants-aleks-carl-sundstroem/ | R25: 2309 | V25: Fra gruppens egen liste | W25: Tidl. politistation
A26: DK-0025 | B26: Bernhard Schermeister | E26: J.M. Thielesvej 1A | F26: 1961 | G26: Frederiksberg C | H26: Frederiksberg | I26: 55.680873 | J26: 12.546459 | K26: snublesten.dk | L26: 2024 | N26: Snublesten Danmark | Q26: https://snublesten.dk/snublesten/bernhard-schermeister/ | R26: 2333 | V26: Fra gruppens egen liste
A27: DK-0026 | B27: Edith Schermeister | E27: J.M. Thielesvej 1A | F27: 1961 | G27: Frederiksberg C | H27: Frederiksberg | I27: 55.680793 | J27: 12.546469 | K27: snublesten.dk | L27: 2024 | N27: Snublesten Danmark | Q27: https://snublesten.dk/snublesten/edith-schermeister/ | R27: 2336 | V27: Fra gruppens egen liste
A28: DK-0027 | B28: Inge Schermeister | E28: J.M. Thielesvej 1A | F28: 1961 | G28: Frederiksberg C | H28: Frederiksberg | I28: 55.680923 | J28: 12.546509 | K28: snublesten.dk | L28: 2024 | N28: Snublesten Danmark | Q28: https://snublesten.dk/snublesten/inge-schermeister/ | R28: 2340 | V28: Fra gruppens egen liste
A29: DK-0028 | B29: Jeanne Schermeister | E29: J.M. Thielesvej 1A | F29: 1961 | G29: Frederiksberg C | H29: Frederiksberg | I29: 55.680903 | J29: 12.546539 | K29: snublesten.dk | L29: 2024 | N29: Snublesten Danmark | Q29: https://snublesten.dk/snublesten/jeanne-schermeister/ | R29: 2341 | V29: Fra gruppens egen liste
A30: DK-0029 | B30: Lis Schermeister | E30: J.M. Thielesvej 1A | F30: 1961 | G30: Frederiksberg C | H30: Frederiksberg | I30: 55.680913 | J30: 12.546389 | K30: snublesten.dk | L30: 2024 | N30: Snublesten Danmark | Q30: https://snublesten.dk/snublesten/lis-schermeister/ | R30: 2337 | V30: Fra gruppens egen liste
A31: DK-0030 | B31: Jonas Bornstein | E31: Julius Thomsens Plads 2 | F31: 1925 | G31: Frederiksberg C | H31: Frederiksberg | I31: 55.680322 | J31: 12.553481 | K31: snublesten.dk | L31: 2024 | N31: Snublesten Danmark | Q31: https://snublesten.dk/snublesten/jonas-bornstein/ | R31: 2366 | V31: Fra gruppens egen liste
A32: DK-0031 | B32: Jytte Bornstein | E32: Julius Thomsens Plads 2 | F32: 1925 | G32: Frederiksberg C | H32: Frederiksberg | I32: 55.680312 | J32: 12.553581 | K32: snublesten.dk | L32: 2024 | N32: Snublesten Danmark | Q32: https://snublesten.dk/snublesten/jytte-bornstein/ | R32: 2356 | V32: Fra gruppens egen liste
A33: DK-0032 | B33: Lilly Bornstein | E33: Julius Thomsens Plads 2 | F33: 1925 | G33: Frederiksberg C | H33: Frederiksberg | I33: 55.680222 | J33: 12.553481 | K33: snublesten.dk | L33: 2024 | N33: Snublesten Danmark | Q33: https://snublesten.dk/snublesten/lilly-bornstein/ | R33: 2363 | V33: Fra gruppens egen liste
A34: DK-0033 | B34: Preben Bornstein | E34: Julius Thomsens Plads 2 | F34: 1925 | G34: Frederiksberg C | H34: Frederiksberg | I34: 55.680372 | J34: 12.553551 | K34: snublesten.dk | L34: 2024 | N34: Snublesten Danmark | Q34: https://snublesten.dk/snublesten/preben-bornstein/ | R34: 2360 | V34: Fra gruppens egen liste
A35: DK-0034 | B35: Kai Adolf Levin | E35: Madvigs Allé 9 | F35: 1829 | G35: Frederiksberg C | H35: Frederiksberg | I35: 55.675484 | J35: 12.540779 | K35: snublesten.dk | L35: 2023 | N35: Snublesten Danmark | Q35: https://snublesten.dk/snublesten/kai-levin/ | R35: 1671 | V35: Fra gruppens egen liste
A36: DK-0035 | B36: Zerline Levin | E36: Madvigs Allé 9 | F36: 1829 | G36: Frederiksberg C | H36: Frederiksberg | I36: 55.675484 | J36: 12.540849 | K36: snublesten.dk | L36: 2023 | N36: Snublesten Danmark | Q36: https://snublesten.dk/snublesten/zerline-levin/ | R36: 1681 | V36: Fra gruppens egen liste
A37: DK-0036 | B37: Irma Hertz | C37: 1878 | D37: Omkom | E37: Vodroffslund 3 | F37: 1419 | G37: Frederiksberg C | H37: Frederiksberg | I37: 55.678245 | J37: 12.553837 | K37: snublesten.dk | L37: 2020 | N37: Snublesten Danmark | P37: HIER WOHNTE / IRMA HERTZ / GEB. ALS LEVY 1878 / VERHAFTET 7.10.1943 / DEPORTIERT / THERESIENSTADT / UMGEKOMMEN 21.12.1943 | Q37: https://snublesten.dk/snublesten/irma-hertz/ | R37: 538 | U37: Stolperstein für Irma Hertz (Frederiksberg).jpg | V37: Fra gruppens egen liste | W37: de.wikipedia angiver adresse 'Vordruffslund 3'
A38: DK-0037 | B38: Hugo Wulff | E38: Ahlmanns Allé 2 | F38: 2900 | G38: Hellerup | H38: Gentofte | I38: 55.73692 | J38: 12.574903 | K38: snublesten.dk | L38: 2026 | N38: Snublesten Danmark | Q38: https://snublesten.dk/snublesten/hugo-wulff/ | R38: 3195 | V38: Fra gruppens egen liste
A39: DK-0038 | B39: Rose Wulff | C39: 1878 | D39: Omkom | E39: Ahlmanns Allé 2 | F39: 2900 | G39: Hellerup | H39: Gentofte | I39: 55.736984 | J39: 12.574764 | K39: snublesten.dk | L39: 2021 | N39: Snublesten Danmark | P39: HIER WOHNTE / ROSE WULFF / GEBOREN 1878 ALS SALOMONSEN / VERHAFTET 1.10.1943 / DEPORTIERT 1943 / THERESIENSTADT / ERMORDET 7.2.1944 | Q39: https://snublesten.dk/snublesten/rose-wulff/ | R39: 1402 | U39: Stolperstein für Rose Wulff (Gentofte).jpg | V39: Fra gruppens egen liste
A40: DK-0039 | B40: Anna Bär | E40: Frugtparken 6 | F40: 2820 | G40: Gentofte | H40: Gentofte | I40: 55.745362 | J40: 12.530049 | K40: snublesten.dk | L40: 2024 | N40: Snublesten Danmark | Q40: https://snublesten.dk/snublesten/anna-bar/ | R40: 2374 | V40: Fra gruppens egen liste
...

Sheet Afvigelser
A1: Sten / emne | B1: Problem | C1: Kilder i konflikt | D1: Forslag til afklaring
A2: Blima Itzkowitz | B2: To forskellige adresser | C2: snublesten.dk: Krystalgade 12 · de.wikipedia: Vibevej 45 | D2: Fotografér stenen eller spørg Snublesten Danmark
A3: Svend Børge Johansen (Odense) | B3: To forskellige efternavne | C3: snublestenfyn.dk: Johansen · Commons-fil: 'Svend Borge Rasmussen' | D3: Tjek fotoet på Commons eller Odense Stadsarkiv
A4: Ellen Wilhelmine Nielsen | B4: Postnr og by passer ikke sammen | C4: snublesten.dk: '2770 Dragør' (2770 = Kastrup, Dragør = 2791) | D4: Koordinaten ligger i Dragør – sandsynligvis forkert postnr
A5: Arthur Ascher | B5: Navnet staves anderledes på stenen | C5: Indskrift ifølge de.wikipedia: 'ARTHUR ASHER' | D5: Tjek foto – hvis stenen er fejlgraveret, noteres det, ikke rettes
A6: Emil Valdemar Abrahamson | B6: Navnet staves anderledes på stenen | C6: Indskrift ifølge de.wikipedia: 'EMIL VALDEMR' | D6: Som ovenfor
A7: Ada Elvira og Gunnar Johan Bomhoff | B7: Adresse-præcision | C7: snublesten.dk: Harsdorffsvej 7 · de.wikipedia: 'Harsdorffsvej/Bomhoffs Have' | D7: Ingen konflikt, men tjek stenens placering
A8: Irma Hertz | B8: Stavemåde af vejnavn | C8: snublesten.dk: Vodroffslund · de.wikipedia: Vordruffslund | D8: Vodroffslund er den gængse stavemåde
A9: Ruth Bertha Nebel, Ulrik Dircks (Odense) | B9: Adresse udledt, ikke oplyst | C9: Kun Commons-fotos af adresser taget samme dag (Buchwaldsgade 38, Bangs Allé 7) | D9: Bekræft hos Snublesten Fyn
A10: 12 OSM-noder i indre København | B10: Uden navn | C10: OpenStreetMap: kun position + link til de.wikipedia | D10: Når registret er bekræftet: tilføj name/inscription/subject:wikidata i OSM
A11: OSM-node 13526817060 ved Horsens | B11: Fejltagget | C11: Krigergrav fra 1866 tagget som memorial=stolperstein | D11: Ret tagget i OSM
A12: Snublesten Danmark: 'Søren Mølllers Gade' | B12: Stavefejl i kilden | C12: Rettet til Søren Møllers Gade i registret | D12: Kan nævnes for gruppen

Sheet Mangler
A1: Område / gruppe | B1: Hvad vi ved | C1: Kilde der skal gennemgås | D1: Status
A2: Fredericia og Taulov | B2: Linket fra snublesten.dk – ingen sten i registret endnu | C2: https://www.fredericiahistorie.dk/side/snublesten-i-fredericia-og-taulov | D2: Ikke indsamlet
A3: Aalborg | B3: Linket fra snublesten.dk – ingen sten i registret endnu | C3: http://snublestenaalborg.dk/ | D3: Ikke indsamlet
A4: Tønder | B4: Linket fra snublesten.dk – ingen sten i registret endnu | C4: https://nisjepsen.dk/skabelon.asp?side=17&subside=53 | D4: Ikke indsamlet
A5: Skærbæk | B5: 3 sten kendt fra Commons-fotos (nedlagt 5. maj 2025), adresser mangler | C5: https://historiskforeningskaerbaek.dk/om/snublesten | D5: Delvist
A6: Frederikshavn Kommune | B6: Nordjyllands Kystmuseums eget projekt | C6: Projektets egne lister / bogen | D6: Tilføjes af Jakob
A7: Vordingborg / Kalvehave | B7: 1 sten (Leo Købmann, 2023) kendt kun fra OpenStreetMap | C7: Lokalarkiv / lokalavis | D7: Delvist
A8: Odense – unavngivne fotos | B8: 17 Commons-fotos 'Stolperstein in Odense N' uden navn | C8: Commons: Category:Stolpersteine in Odense | D8: Kan bruges til at bekræfte indskrifter
A9: Dansk original-indskrift | B9: Kun 6 af stenene har den danske tekst registreret | C9: Fotos på Commons og hos grupperne | D9: Største hul i datasættet

Sheet Felter
A1: Felt | B1: Betydning | C1: Hvem udfylder
A2: ID | B2: Registrets eget løbenummer. Ændres ikke, når det først er tildelt. | C2: Claude / import
A3: Navn | C3: Claude / import
A4: Født (år) | C4: Claude / import
A5: Udfald | B5: Omkom / Overlevede – udledt af indskriften. Tomt hvor indskriften mangler. | C5: Claude / import
A6: Adresse | C6: Claude / import
A7: Postnr | C7: Claude / import
A8: By | C8: Claude / import
A9: Kommune | C9: Claude / import
A10: Bredde | C10: Claude / import
A11: Længde | C11: Claude / import
A12: Koordinat-kilde | B12: Hvor koordinaten kommer fra (snublesten.dk, Commons-foto, OSM). | C12: Claude / import
A13: Nedlagt (år) | C13: Claude / import
A14: Nedlagt (dato) | C14: Claude / import
A15: Sat af | B15: Gruppen der satte stenen. | C15: Claude / import
A16: Indskrift (dansk, original) | B16: Den danske tekst på stenen, ordret. Den vigtigste mangel. | C16: Du
A17: Indskrift (tysk oversættelse, de.wikipedia) | B17: Tysk oversættelse fra de.wikipedia – ikke stenens egen tekst. | C17: Claude / import
A18: Primær kilde | B18: Den side oplysningerne primært er hentet fra. | C18: Claude / import
A19: snublesten.dk-ID | C19: Claude / import
A20: Wikidata | C20: Claude / import
A21: OSM-node | B21: '(?)' betyder: noden ligger ved adressen, men har intet navn – hvilken sten den er, er ikke afgjort. | C21: Claude / import
A22: Commons-foto | C22: Claude / import
A23: Status | B23: Fra gruppens egen liste / Fra gruppens egen side / Skal verificeres / Afvigelse – tjek | C23: Du
A24: Note | B24: Afvigelser, udledninger og forbehold. | C24: Du
A26: Rediger især | B26: Indskrift (dansk), Status og Note. Nye sten tilføjes nederst i Register – tabellen udvider sig selv, og Oversigt tæller med.
A27: Eksempelrække | B27: DK-0148 Pinkus Katz er den mest komplette række: alle felter udfyldt fra fire kilder.
A28: Rettigheder | B28: Navne, adresser, datoer og koordinater er fakta. Biografier og fotos hos grupperne er ophavsretligt beskyttede og er ikke kopieret. Publicér ikke registret som eget datasæt før aftale med grupperne.
